Workbook

Sheet Ingresos
A1: Fecha | B1: Cliente | C1: Proyecto | D1: Estado del proyecto | E1: Monto ARS | F1: Monto USD | G1: Tipo de Ingreso | H1: Reservado | I1: Monto Reservado | J1: Observaciones
A2: 45909 | B2: PACSA | C2: Automatizacion WhatsApp | D2: Activo | E2: 150000 | F2: 108.3 | G2: Adelanto | I2: =IFERROR(E2*H2,0) -> 0
A3: 45923 | B3: PACSA | C3: Automatizacion WhatsApp | D3: Activo | E3: 150000 | F3: 101.69 | G3: Pago final | I3: =IFERROR(E3*H3,0) -> 0
A4: 45923 | B4: PACSA | C4: Automatizacion WhatsApp | D4: Activo | E4: 360000 | F4: 244.07 | G4: Recurrente | I4: =IFERROR(E4*H4,0) -> 0 | J4: Pagado hasta febrero 2026 inclusive
A5: 45939 | B5: COIRINI | C5: Gestion RRSS | D5: Activo | E5: 180000 | F5: 122.03 | G5: Recurrente | I5: =IFERROR(E5*H5,0) -> 0
A6: 45965 | B6: PACSA | C6: Lista de difusión | D6: Activo | E6: 150000 | F6: 102.74 | G6: Pago final | I6: =IFERROR(E6*H6,0) -> 0
A7: 45965 | B7: PACSA | C7: Lista de difusión | D7: Activo | E7: 180000 | F7: 123.29 | G7: Recurrente | I7: =IFERROR(E7*H7,0) -> 0 | J7: Pagado hasta marzo 2026 inclusive
A8: 45972 | B8: COIRINI | C8: Gestion RRSS | D8: Activo | E8: 180000 | F8: 126.32 | G8: Recurrente | I8: =IFERROR(E8*H8,0) -> 0
A9: 45975 | B9: COLEGIO | C9: Estampilla Digital | D9: Activo | E9: 4800000 | F9: 3344.95 | G9: Adelanto | I9: =IFERROR(E9*H9,0) -> 0 | J9: 40% del total
A10: 45994 | B10: FAUFENA | C10: Plataforma B2B | D10: Activo | E10: 500000 | F10: 346.02 | G10: Adelanto | I10: =IFERROR(E10*H10,0) -> 0 | J10: 50% del total
A11: 45999 | B11: Nico Oliveto | C11: Soporte | D11: Activo | E11: 30000 | F11: 20.91 | G11: Pago final | I11: =IFERROR(E11*H11,0) -> 0
A12: 46011 | B12: COIRINI | C12: Gestion RRSS | D12: Activo | E12: 195000 | F12: 131.31 | G12: Recurrente | I12: =IFERROR(E12*H12,0) -> 0
A13: 46048 | B13: BERTINO | C13: Sitio Web | D13: Activo | E13: 594000 | F13: 400 | G13: Adelanto | I13: =IFERROR(E13*H13,0) -> 0
A14: 46058 | B14: BERTINO | C14: Sitio Web | D14: Activo | E14: 582000 | F14: 400 | G14: Pago final | I14: =IFERROR(E14*H14,0) -> 0 | J14: 50% restante Sitio Web
A15: 46058 | B15: BERTINO | C15: Sitio Web | D15: Activo | E15: 698400 | F15: 480 | G15: Recurrente | I15: =IFERROR(E15*H15,0) -> 0 | J15: Mantenimiento mensual Sitio Web hasta Febrero 2027 inclusive
A16: 46072 | B16: COIRINI | C16: Gestion RRSS | D16: Activo | E16: 390000 | F16: 276.6 | G16: Recurrente | I16: =IFERROR(E16*H16,0) -> 0 | J16: Diciembre y Enero
A17: 46080 | B17: PACSA | C17: Automatizacion WhatsApp | D17: Activo | E17: 720000 | F17: 505.26 | G17: Recurrente | I17: =IFERROR(E17*H17,0) -> 0 | J17: Marzo a Agosto 2026 inclusive
A18: 46073 | B18: COLEGIO | C18: Firma Digital | D18: Finalizado | E18: 235000 | F18: 165.5 | G18: Pago final | I18: =IFERROR(E18*H18,0) -> 0 | J18: Pago unico
A19: 46079 | B19: COLEGIO | C19: Estampilla Digital | D19: Activo | E19: 3600000 | F19: =E19/1435.21 -> 2508.3437 | G19: Adelanto | I19: =IFERROR(E19*H19,0) -> 0
A20: 46083 | E20: 1165217.9 | F20: =E20/1428.17 -> 815.88178 | I20: =IFERROR(E20*H20,0) -> 0 | J20: Ajuste por intereses
A21: 46085 | B21: RASAFERTIL | C21: Sitio Web | D21: Activo | E21: 350000 | F21: =E21/1434.29 -> 244.02318 | G21: Adelanto | I21: =IFERROR(E21*H21,0) -> 0 | J21: 50% Sitio Web
A22: 46090 | B22: UN TOQUE DE AMOR | C22: eCommerce | D22: Activo | F22: 465 | G22: Adelanto | I22: =IFERROR(E22*H22,0) -> 0 | J22: 465 de 1400
A23: 46093 | B23: COLEGIO | C23: Digitalización Documentos | D23: Activo | E23: 2850000 | F23: =E23/1424 -> 2001.4045 | G23: Adelanto | I23: =IFERROR(E23*H23,0) -> 0 | J23: 30% inicial
I24: =IFERROR(E24*H24,0) -> 0
I25: =IFERROR(E25*H25,0) -> 0
I26: =IFERROR(E26*H26,0) -> 0
I27: =IFERROR(E27*H27,0) -> 0
E28: =SUM(Ingresos[Monto ARS]) -> 18059618 | F28: =SUM(Ingresos[Monto USD]) -> 13033.643 | I28: =SUM(Ingresos[Monto Reservado]) -> 0

Sheet Gastos
A1: Fecha | B1: Tipo de Gasto | C1: Categoría | D1: Proyecto (si aplica) | E1: Estado del proyecto | F1: Monto ARS | G1: Monto USD | H1: Observaciones
A2: 45937 | B2: Variable | C2: Infra/Cloud | F2: 21600 | G2: 15 | H2: Rackspace
A3: 45937 | B3: Fijo | C3: Herramientas/Software | F3: 28800 | G3: 20 | H3: ChatGPT
A4: 45937 | B4: Fijo | C4: Herramientas/Software | F4: 28800 | G4: 20 | H4: v0
A5: 45937 | B5: Variable | C5: Publicidad (ads) | F5: 28800 | G5: 20 | H5: LinkedIn
A6: 45932 | B6: Fijo | C6: Marketing | F6: 150000 | G6: 101.69 | H6: Mehc
A7: 45932 | B7: Fijo | C7: Marketing | F7: 150000 | G7: 101.69 | H7: Mehc - Tercerización RRSS Coirini
A8: 45923 | B8: Fijo | C8: Contabilidad/Legal | F8: 37085.74 | G8: 25.14 | H8: Monotributo
A9: 45943 | B9: Fijo | C9: Contabilidad/Legal | F9: 9277 | G9: 6.27 | H9: IIBB
A10: 45950 | B10: Fijo | C10: Contabilidad/Legal | F10: 37085.74 | G10: 25.23 | H10: Monotributo
A11: 45964 | B11: Fijo | C11: Marketing | F11: 150000 | G11: 102.39 | H11: Mehc
A12: 45964 | B12: Fijo | C12: Marketing | F12: 150000 | G12: 102.39 | H12: Mehc - Tercerización RRSS Coirini
A13: 45965 | B13: Fijo | C13: Herramientas/Software | F13: =20*1450 -> 29000 | G13: 20 | H13: ChatGPT
A14: 45965 | B14: Fijo | C14: Herramientas/Software | F14: =20*1450 -> 29000 | G14: 20 | H14: v0
A15: 45965 | B15: Variable | C15: Infra/Cloud | F15: =25.1*1450 -> 36395 | G15: 25.1 | H15: Rackspace
A16: 45971 | B16: Fijo | C16: Contabilidad/Legal | F16: 9277 | G16: 6.51 | H16: IIBB
A17: 45993 | B17: Fijo | C17: Marketing | F17: 150000 | G17: 104.17 | H17: Mehc
A18: 45993 | B18: Fijo | C18: Marketing | F18: 150000 | G18: 104.17 | H18: Mehc - Tercerización RRSS Coirini
A19: 45994 | B19: Fijo | C19: Herramientas/Software | F19: =20*1445 -> 28900 | G19: 20 | H19: ChatGPT
A20: 45994 | B20: Fijo | C20: Herramientas/Software | F20: =20*1445 -> 28900 | G20: 20 | H20: v0
A21: 45994 | B21: Variable | C21: Infra/Cloud | F21: =25.03*1445 -> 36168.35 | G21: 25.03 | H21: Rackspace
A22: 45994 | B22: Variable | C22: Infra/Cloud | F22: =12.78*1445 -> 18467.1 | G22: 12.78 | H22: GCP
A23: 45999 | B23: Fijo | C23: Contabilidad/Legal | F23: 9277 | G23: 6.46 | H23: IIBB
A24: 46013 | B24: Fijo | C24: Contabilidad/Legal | F24: 37095 | G24: 24.9 | H24: Monotributo
A25: 46027 | B25: Fijo | C25: Marketing | F25: 330000 | G25: 220.74 | H25: Mehc + Coirini
A26: 46027 | B26: Variable | C26: Herramientas/Software | F26: 137273.33 | G26: 91.82 | H26: V0 + Chat + Rackspace + GCP
A27: 46035 | B27: Fijo | C27: Contabilidad/Legal | F27: 9277 | G27: 6.29 | H27: IIBB
A28: 46042 | B28: Fijo | C28: Contabilidad/Legal | F28: 37086 | G28: 25.31 | H28: Monotributo
A29: 46053 | B29: Variable | C29: Marketing | F29: 50000 | G29: 34 | H29: Stickers
A30: 46055 | B30: Fijo | C30: Marketing | F30: 330000 | G30: 226 | H30: Mehc + Coirini
A31: 46057 | B31: Fijo | C31: Herramientas/Software | G31: 40 | H31: v0
A32: 46057 | B32: Variable | C32: Infra/Cloud | G32: 20 | H32: ChatGPT
A33: 46057 | B33: Variable | C33: Infra/Cloud | G33: 46.08 | H33: GCP
A34: 46071 | B34: Fijo | C34: Contabilidad/Legal | F34: 43386.74 | G34: 30.77 | H34: Monotributo
A35: 46071 | B35: Fijo | C35: Contabilidad/Legal | F35: 10500 | G35: 7.44 | H35: IIBB
A36: 46077 | B36: Variable | C36: Contabilidad/Legal | F36: 35360 | G36: =F36/1425 -> 24.814035 | H36: Registro de marca
A37: 46079 | B37: Variable | C37: Hardware | F37: 190000 | G37: =F37/1435.21 -> 132.38481 | H37: Memoria RAM Tomas
A38: 46080 | B38: Fijo | C38: Sueldos/Honorarios | F38: 2000000 | G38: =F38/1428.17 -> 1400.3935 | H38: 750 usd c/u
A39: 46083 | B39: Variable | C39: Herramientas/Software | G39: 40.06 | H39: GCP
A40: 46083 | B40: Fijo | C40: Herramientas/Software | G40: 30.59 | H40: v0
...

Sheet Distribución
A1: Mes a consultar: | B1: 46082 | E1: CELDAS EN ESTE COLOR SE ACTUALIZAN AUTOMATICAMENTE
A3: Capa 1 (Emergencia) - Total Acumulado: | B3: 2000 | C3: Cocos Capital
A4: Capa 2 (Crecimiento) - Total Acumulado: | B4: 4000 | C4: Naranja X
A5: Capa 4 (Remanente) - Total Histórico: | B5: =SUM(Ingresos!F:F) - SUM(Gastos!G:G) - B3 - B4 -> 16451.301
A7: Retirado por sueldo este mes: | B7: =SUMIFS(Gastos!G:G, Gastos!A:A, ">="&EOMONTH($B$1,-1)+1, Gastos!A:A, "<="&EOMONTH($B$1,0), Gastos!C:C, "Sueldos/Honorarios") -> 0

Sheet Resumen
A2: Resumen por período
D3: Categoría | E3: Fijos | F3: Variables (Activos) | G3: Total | I3: Tipo | J3: Total | L3: Tips:
A4: Fecha inicio (incluye) | B4: 45870 | D4: Marketing | E4: =SUMIFS(Gastos!G:G,Gastos!A:A,">="&$B$4,Gastos!A:A,"<"&$B$5,Gastos!B:B,"Fijo",Gastos!C:C,"Marketing") -> 1294.3049 | F4: =SUMIFS(Gastos!G:G,Gastos!A:A,">="&$B$4,Gastos!A:A,"<"&$B$5,Gastos!B:B,"Variable",Gastos!C:C,"Marketing") -> 34 | G4: =E4+F4 -> 1328.3049 | I4: Adelanto | J4: =SUMIFS(Ingresos!F:F, Ingresos!A:A, ">="&$B$4, Ingresos!A:A, "<"&$B$5, Ingresos!G:G, I4) -> 9418.0414 | L4: - Filtrá en 'Ingresos' y 'Gastos' por 'Estado del proyecto' = Activo para análisis operativo, o quitalo para históricos.
A5: Fecha fin (excluye) | B5: =EDATE(B4,12) -> 46235 | D5: Herramientas/Software | E5: =SUMIFS(Gastos!G:G,Gastos!A:A,">="&$B$4,Gastos!A:A,"<"&$B$5,Gastos!B:B,"Fijo",Gastos!C:C,"Herramientas/Software") -> 210.59 | F5: =SUMIFS(Gastos!G:G,Gastos!A:A,">="&$B$4,Gastos!A:A,"<"&$B$5,Gastos!B:B,"Variable",Gastos!C:C,"Herramientas/Software") -> 131.88 | G5: =E5+F5 -> 342.47 | I5: Pago final | J5: =SUMIFS(Ingresos!F:F, Ingresos!A:A, ">="&$B$4, Ingresos!A:A, "<"&$B$5, Ingresos!G:G, I5) -> 790.84 | L5: - Completá '% Reservado' en 'Ingresos' para proyectos estratégicos (ej. Estampilla Digital).
D6: Hardware | E6: =SUMIFS(Gastos!G:G,Gastos!A:A,">="&$B$4,Gastos!A:A,"<"&$B$5,Gastos!B:B,"Fijo",Gastos!C:C,"Hardware") -> 0 | F6: =SUMIFS(Gastos!G:G,Gastos!A:A,">="&$B$4,Gastos!A:A,"<"&$B$5,Gastos!B:B,"Variable",Gastos!C:C,"Hardware") -> 132.38481 | G6: =E6+F6 -> 132.38481 | I6: Recurrente | J6: =SUMIFS(Ingresos!F:F, Ingresos!A:A, ">="&$B$4, Ingresos!A:A, "<"&$B$5, Ingresos!G:G, I6) -> 2008.88 | L6: - 'Categoría' de Gastos tiene lista desplegable editable en la hoja oculta 'Listas'.
A7: Ingresos | B7: =SUMIFS(Ingresos!F:F, Ingresos!A:A, ">="&B4, Ingresos!A:A, "<"&B5) -> 13033.643 | D7: Infra/Cloud | E7: =SUMIFS(Gastos!G:G,Gastos!A:A,">="&$B$4,Gastos!A:A,"<"&$B$5,Gastos!B:B,"Fijo",Gastos!C:C,"Infra/Cloud") -> 0 | F7: =SUMIFS(Gastos!G:G,Gastos!A:A,">="&$B$4,Gastos!A:A,"<"&$B$5,Gastos!B:B,"Variable",Gastos!C:C,"Infra/Cloud") -> 143.99 | G7: =E7+F7 -> 143.99 | I7: TOTAL | J7: =SUM(Resumen_Ingresos[Total]) -> 12217.761
A8: Gastos Fijos | B8: =SUMIFS(Gastos!G:G, Gastos!A:A, ">="&$B$4, Gastos!A:A, "<"&$B$5, Gastos!B:B, "Fijo") -> 3069.6084 | D8: Hosting/Dominios | E8: =SUMIFS(Gastos!G:G,Gastos!A:A,">="&$B$4,Gastos!A:A,"<"&$B$5,Gastos!B:B,"Fijo",Gastos!C:C,"Hosting/Dominios") -> 0 | F8: =SUMIFS(Gastos!G:G,Gastos!A:A,">="&$B$4,Gastos!A:A,"<"&$B$5,Gastos!B:B,"Variable",Gastos!C:C,"Hosting/Dominios") -> 0 | G8: =E8+F8 -> 0
A9: Gastos Variables | B9: =SUMIFS(Gastos!G:G, Gastos!A:A, ">="&$B$4, Gastos!A:A, "<"&$B$5, Gastos!B:B, "Variable") -> 546.37643 | D9: Email | E9: =SUMIFS(Gastos!G:G,Gastos!A:A,">="&$B$4,Gastos!A:A,"<"&$B$5,Gastos!B:B,"Fijo",Gastos!C:C,"Email/Zoho") -> 0 | F9: =SUMIFS(Gastos!G:G,Gastos!A:A,">="&$B$4,Gastos!A:A,"<"&$B$5,Gastos!B:B,"Variable",Gastos!C:C,"Email/Zoho") -> 0 | G9: =E9+F9 -> 0
D10: Publicidad (Ads) | E10: =SUMIFS(Gastos!G:G,Gastos!A:A,">="&$B$4,Gastos!A:A,"<"&$B$5,Gastos!B:B,"Fijo",Gastos!C:C,"Publicidad (Ads)") -> 0 | F10: =SUMIFS(Gastos!G:G,Gastos!A:A,">="&$B$4,Gastos!A:A,"<"&$B$5,Gastos!B:B,"Variable",Gastos!C:C,"Publicidad (Ads)") -> 20 | G10: =E10+F10 -> 20
A11: Resultado Neto | B11: =B7-B8-B9 -> 9417.6583 | D11: Sueldos/Honorarios | E11: =SUMIFS(Gastos!G:G,Gastos!A:A,">="&$B$4,Gastos!A:A,"<"&$B$5,Gastos!B:B,"Fijo",Gastos!C:C,"Sueldos/Honorarios") -> 1400.3935 | F11: =SUMIFS(Gastos!G:G,Gastos!A:A,">="&$B$4,Gastos!A:A,"<"&$B$5,Gastos!B:B,"Variable",Gastos!C:C,"Sueldos/Honorarios") -> 0 | G11: =E11+F11 -> 1400.3935
D12: Contabilidad/Legal | E12: =SUMIFS(Gastos!G:G,Gastos!A:A,">="&$B$4,Gastos!A:A,"<"&$B$5,Gastos!B:B,"Fijo",Gastos!C:C,"Contabilidad/Legal") -> 164.32 | F12: =SUMIFS(Gastos!G:G,Gastos!A:A,">="&$B$4,Gastos!A:A,"<"&$B$5,Gastos!B:B,"Variable",Gastos!C:C,"Contabilidad/Legal") -> 24.814035 | G12: =E12+F12 -> 189.13404
A13: Reserva acumulada (Activos) | B13: =SUMIFS(Ingresos!H:H,Ingresos!A:A,">="&B4,Ingresos!A:A,"<"&B5,Ingresos!D:D,"Activo") -> 0 | D13: Viajes/Viáticos | E13: =SUMIFS(Gastos!G:G,Gastos!A:A,">="&$B$4,Gastos!A:A,"<"&$B$5,Gastos!B:B,"Fijo",Gastos!C:C,"Viajes/Viáticos") -> 0 | F13: =SUMIFS(Gastos!G:G,Gastos!A:A,">="&$B$4,Gastos!A:A,"<"&$B$5,Gastos!B:B,"Variable",Gastos!C:C,"Viajes/Viáticos") -> 10.502951 | G13: =E13+F13 -> 10.502951
D14: Prospección/Demos | E14: =SUMIFS(Gastos!G:G,Gastos!A:A,">="&$B$4,Gastos!A:A,"<"&$B$5,Gastos!B:B,"Fijo",Gastos!C:C,"Prospección/Demos") -> 0 | F14: =SUMIFS(Gastos!G:G,Gastos!A:A,">="&$B$4,Gastos!A:A,"<"&$B$5,Gastos!B:B,"Variable",Gastos!C:C,"Prospección/Demos") -> 48.804635 | G14: =E14+F14 -> 48.804635
D15: Otros | E15: =SUMIFS(Gastos!G:G,Gastos!A:A,">="&$B$4,Gastos!A:A,"<"&$B$5,Gastos!B:B,"Fijo",Gastos!C:C,"Otros") -> 0 | F15: =SUMIFS(Gastos!G:G,Gastos!A:A,">="&$B$4,Gastos!A:A,"<"&$B$5,Gastos!B:B,"Variable",Gastos!C:C,"Otros") -> 0 | G15: =E15+F15 -> 0
D16: TOTAL | E16: =SUM(Resumen_Gastos[Fijos]) -> 3069.6084 | F16: =SUM(Resumen_Gastos[Variables (Activos)]) -> 546.37643 | G16: =SUM(Resumen_Gastos[Total]) -> 3615.9849

Sheet Listas
A1: Estados | C1: TiposIngreso | E1: TiposGasto | G1: CategoriasGasto
A2: Activo | C2: Adelanto | E2: Fijo | G2: Marketing
A3: Finalizado | C3: Pago final | E3: Variable | G3: Herramientas/Software
A4: Cancelado | C4: Recurrente | G4: Infra/Cloud
G5: Hosting/Dominios
G6: Email/Zoho
G7: Publicidad (Ads)
G8: Sueldos/Honorarios
G9: Contabilidad/Legal
G10: Viajes/Viáticos
G11: Prospección/Demos
G12: Otros
